[2025-05-05 11:59:27,472] 97 werkzeug - WARNING -  * Debugger is active!
[2025-05-05 11:59:27,475] 97 werkzeug - INFO -  * Debugger PIN: 143-783-530
[2025-05-05 11:59:29,744] 97 werkzeug - INFO - 127.0.0.1 - - [05/May/2025 11:59:29] "GET / HTTP/1.1" 200 -
[2025-05-05 11:59:29,821] 97 werkzeug - INFO - 127.0.0.1 - - [05/May/2025 11:59:29] "[36mGET /static/style.css HTTP/1.1[0m" 304 -
[2025-05-05 11:59:51,451] 34 root - INFO - Received form data:
[2025-05-05 11:59:51,454] 37 root - INFO - Location: washington
[2025-05-05 11:59:51,454] 37 root - INFO - Temperature: 23
[2025-05-05 11:59:51,454] 37 root - INFO - Humidity: 12
[2025-05-05 11:59:51,494] 37 root - INFO - Wind_Speed: 60
[2025-05-05 11:59:51,494] 37 root - INFO - Precipitation: 23
[2025-05-05 11:59:51,495] 37 root - INFO - Cloud_Cover: partly cloudy
[2025-05-05 11:59:51,495] 59 root - INFO - Input data validated and created
[2025-05-05 11:59:51,495] 62 root - INFO - Dataframe Gathered
[2025-05-05 11:59:51,495] 63 root - INFO - Input DataFrame created:
[2025-05-05 11:59:51,505] 64 root - INFO - 
     Location  Temperature  Humidity  Wind_Speed  Precipitation    Cloud_Cover
0  washington         23.0      12.0        60.0           23.0  partly cloudy
[2025-05-05 11:59:51,505] 67 root - INFO - Initializing PredictPipeline...
[2025-05-05 11:59:51,505] 69 root - INFO - Making prediction...
[2025-05-05 11:59:51,505] 53 root - INFO - Exception Occured in load_object function utils
[2025-05-05 11:59:51,505] 81 root - ERROR - Prediction error: Error occured in python script name [C:\Users\Praveen\OneDrive\Desktop\weather_prediction\src\Weather_prediction\pipelines\Prediction_pipeline.py] line number [18] error message [Error occured in python script name [C:\Users\Praveen\OneDrive\Desktop\weather_prediction\src\Weather_prediction\utils\utils.py] line number [50] error message [[Errno 2] No such file or directory: 'Artifacts\\preprocessor.pkl']]
Traceback (most recent call last):
  File "C:\Users\Praveen\OneDrive\Desktop\weather_prediction\src\Weather_prediction\utils\utils.py", line 50, in load_object
    with open(file_path,'rb') as file_obj:
         ^^^^^^^^^^^^^^^^^^^^
FileNotFoundError: [Errno 2] No such file or directory: 'Artifacts\\preprocessor.pkl'

During handling of the above exception, another exception occurred:

Traceback (most recent call last):
  File "C:\Users\Praveen\OneDrive\Desktop\weather_prediction\src\Weather_prediction\pipelines\Prediction_pipeline.py", line 18, in predict
    preprocessor=load_object(preprocessor_path)
                 ^^^^^^^^^^^^^^^^^^^^^^^^^^^^^^
  File "C:\Users\Praveen\OneDrive\Desktop\weather_prediction\src\Weather_prediction\utils\utils.py", line 54, in load_object
    raise customexception(e,sys)
src.Weather_prediction.exception.customexception: Error occured in python script name [C:\Users\Praveen\OneDrive\Desktop\weather_prediction\src\Weather_prediction\utils\utils.py] line number [50] error message [[Errno 2] No such file or directory: 'Artifacts\\preprocessor.pkl']

During handling of the above exception, another exception occurred:

Traceback (most recent call last):
  File "C:\Users\Praveen\OneDrive\Desktop\weather_prediction\app.py", line 72, in predict_datapoint
    results = predict_pipeline.predict(pred_df)
              ^^^^^^^^^^^^^^^^^^^^^^^^^^^^^^^^^
  File "C:\Users\Praveen\OneDrive\Desktop\weather_prediction\src\Weather_prediction\pipelines\Prediction_pipeline.py", line 30, in predict
    raise customexception(e,sys)
src.Weather_prediction.exception.customexception: Error occured in python script name [C:\Users\Praveen\OneDrive\Desktop\weather_prediction\src\Weather_prediction\pipelines\Prediction_pipeline.py] line number [18] error message [Error occured in python script name [C:\Users\Praveen\OneDrive\Desktop\weather_prediction\src\Weather_prediction\utils\utils.py] line number [50] error message [[Errno 2] No such file or directory: 'Artifacts\\preprocessor.pkl']]
[2025-05-05 11:59:51,508] 90 root - ERROR - Error in predict_datapoint: An error occurred: Prediction failed: Error occured in python script name [C:\Users\Praveen\OneDrive\Desktop\weather_prediction\src\Weather_prediction\pipelines\Prediction_pipeline.py] line number [18] error message [Error occured in python script name [C:\Users\Praveen\OneDrive\Desktop\weather_prediction\src\Weather_prediction\utils\utils.py] line number [50] error message [[Errno 2] No such file or directory: 'Artifacts\\preprocessor.pkl']]

Traceback:
  File "C:\Users\Praveen\OneDrive\Desktop\weather_prediction\app.py", line 72, in predict_datapoint
    results = predict_pipeline.predict(pred_df)
              ^^^^^^^^^^^^^^^^^^^^^^^^^^^^^^^^^
  File "C:\Users\Praveen\OneDrive\Desktop\weather_prediction\src\Weather_prediction\pipelines\Prediction_pipeline.py", line 30, in predict
    raise customexception(e,sys)
Traceback (most recent call last):
  File "C:\Users\Praveen\OneDrive\Desktop\weather_prediction\src\Weather_prediction\utils\utils.py", line 50, in load_object
    with open(file_path,'rb') as file_obj:
         ^^^^^^^^^^^^^^^^^^^^
FileNotFoundError: [Errno 2] No such file or directory: 'Artifacts\\preprocessor.pkl'

During handling of the above exception, another exception occurred:

Traceback (most recent call last):
  File "C:\Users\Praveen\OneDrive\Desktop\weather_prediction\src\Weather_prediction\pipelines\Prediction_pipeline.py", line 18, in predict
    preprocessor=load_object(preprocessor_path)
                 ^^^^^^^^^^^^^^^^^^^^^^^^^^^^^^
  File "C:\Users\Praveen\OneDrive\Desktop\weather_prediction\src\Weather_prediction\utils\utils.py", line 54, in load_object
    raise customexception(e,sys)
src.Weather_prediction.exception.customexception: Error occured in python script name [C:\Users\Praveen\OneDrive\Desktop\weather_prediction\src\Weather_prediction\utils\utils.py] line number [50] error message [[Errno 2] No such file or directory: 'Artifacts\\preprocessor.pkl']

During handling of the above exception, another exception occurred:

Traceback (most recent call last):
  File "C:\Users\Praveen\OneDrive\Desktop\weather_prediction\app.py", line 72, in predict_datapoint
    results = predict_pipeline.predict(pred_df)
              ^^^^^^^^^^^^^^^^^^^^^^^^^^^^^^^^^
  File "C:\Users\Praveen\OneDrive\Desktop\weather_prediction\src\Weather_prediction\pipelines\Prediction_pipeline.py", line 30, in predict
    raise customexception(e,sys)
src.Weather_prediction.exception.customexception: Error occured in python script name [C:\Users\Praveen\OneDrive\Desktop\weather_prediction\src\Weather_prediction\pipelines\Prediction_pipeline.py] line number [18] error message [Error occured in python script name [C:\Users\Praveen\OneDrive\Desktop\weather_prediction\src\Weather_prediction\utils\utils.py] line number [50] error message [[Errno 2] No such file or directory: 'Artifacts\\preprocessor.pkl']]

During handling of the above exception, another exception occurred:

Traceback (most recent call last):
  File "C:\Users\Praveen\OneDrive\Desktop\weather_prediction\app.py", line 86, in predict_datapoint
    raise RuntimeError(error_msg)
RuntimeError: Prediction failed: Error occured in python script name [C:\Users\Praveen\OneDrive\Desktop\weather_prediction\src\Weather_prediction\pipelines\Prediction_pipeline.py] line number [18] error message [Error occured in python script name [C:\Users\Praveen\OneDrive\Desktop\weather_prediction\src\Weather_prediction\utils\utils.py] line number [50] error message [[Errno 2] No such file or directory: 'Artifacts\\preprocessor.pkl']]

Traceback:
  File "C:\Users\Praveen\OneDrive\Desktop\weather_prediction\app.py", line 72, in predict_datapoint
    results = predict_pipeline.predict(pred_df)
              ^^^^^^^^^^^^^^^^^^^^^^^^^^^^^^^^^
  File "C:\Users\Praveen\OneDrive\Desktop\weather_prediction\src\Weather_prediction\pipelines\Prediction_pipeline.py", line 30, in predict
    raise customexception(e,sys)

[2025-05-05 11:59:51,511] 97 werkzeug - INFO - 127.0.0.1 - - [05/May/2025 11:59:51] "[31m[1mPOST /predict HTTP/1.1[0m" 400 -
[2025-05-05 12:02:53,861] 97 werkzeug - INFO -  * Detected change in 'C:\\Users\\Praveen\\OneDrive\\Desktop\\weather_prediction\\train.py', reloading
